<?xml version="1.0" ?>
<!-- Generated using onshape-to-robot -->
<!-- Onshape https://cad.onshape.com/documents/03d3216bcac5903908a6e0de/w/9c3caedc2611d4b7bfb40d56/e/51bba218a52e667b44432352 -->
<mujoco model="arm_150_mass_b">
  <compiler angle="radian" meshdir="assets" autolimits="true"/>
  <default>
    <default class="arm_150_mass_b">
       <joint 
        armature="0.026176125067127395" 
        frictionloss="0.09090098640882"
        damping="1.2965935100389328"
      />
      <default class="visual">
        <geom type="mesh" contype="0" conaffinity="0" group="2"/>
      </default>
      <default class="collision">
        <geom group="3"/>
      </default>
    </default>
  </default>
  <worldbody>
    <!-- Link motor_holder__configuration__1lb -->
    <body name="motor_holder__configuration__1lb" pos="0 0 0" quat="1 0 0 0" childclass="arm_150_mass_b">
      <inertial pos="8.90348e-08 0.0151625 0.0438794" mass="0.0593939" fullinertia="4.21552e-05 1.0144e-05 4.23761e-05 -9.45235e-12 1.06843e-10 -5.33782e-06"/>
      <!-- Part sts3215 -->
      <geom type="mesh" class="visual" pos="6.93893e-18 -0.0096 0.025435" quat="2.4677e-16 -0.707107 -3.14018e-16 -0.707107" mesh="sts3215" material="sts3215_material"/>
      <geom type="mesh" class="collision" pos="6.93893e-18 -0.0096 0.025435" quat="2.4677e-16 -0.707107 -3.14018e-16 -0.707107" mesh="sts3215" material="sts3215_material"/>
      <!-- Part motor_holder__configuration__1lb -->
      <geom type="mesh" class="visual" pos="0 0 0" quat="1 0 0 0" mesh="motor_holder__configuration__1lb" material="motor_holder__configuration__1lb_material"/>
      <geom type="mesh" class="collision" pos="0 0 0" quat="1 0 0 0" mesh="motor_holder__configuration__1lb" material="motor_holder__configuration__1lb_material"/>
      <!-- Link axle_a__configuration__1lb -->
      <body name="axle_a__configuration__1lb" pos="1.38708e-17 -0.0187997 -6.5e-05" quat="0.5 -0.5 -0.5 -0.5">
        <!-- Joint from motor_holder__configuration__1lb to axle_a__configuration__1lb -->
        <joint name="sts3215" type="hinge" range="-1.684242728174528 1.684242728174528"/>
        <inertial pos="-0.144954 -1.12699e-17 0.0189537" mass="0.585" fullinertia="0.000678437 0.000939374 0.00149505 -5.27706e-20 1.63425e-06 -1.29822e-20"/>
        <!-- Part spacer4__configuration__1lb -->
        <geom type="mesh" class="visual" pos="-1.83501e-17 -1.8687e-17 0.01905" quat="0.5 0.5 0.5 0.5" mesh="spacer4__configuration__1lb" material="spacer4__configuration__1lb_material"/>
        <geom type="mesh" class="collision" pos="-1.83501e-17 -1.8687e-17 0.01905" quat="0.5 0.5 0.5 0.5" mesh="spacer4__configuration__1lb" material="spacer4__configuration__1lb_material"/>
        <!-- Part axle_a__configuration__1lb -->
        <geom type="mesh" class="visual" pos="-1.60733e-17 -1.92113e-18 0.0188" quat="0.5 0.5 0.5 0.5" mesh="axle_a__configuration__1lb" material="axle_a__configuration__1lb_material"/>
        <geom type="mesh" class="collision" pos="-1.60733e-17 -1.92113e-18 0.0188" quat="0.5 0.5 0.5 0.5" mesh="axle_a__configuration__1lb" material="axle_a__configuration__1lb_material"/>
        <!-- Part disc_b__configuration__1lb -->
        <geom type="mesh" class="visual" pos="-2.35814e-17 -5.80793e-19 0.01905" quat="0.5 0.5 0.5 0.5" mesh="disc_b__configuration__1lb" material="disc_b__configuration__1lb_material"/>
        <geom type="mesh" class="collision" pos="-2.35814e-17 -5.80793e-19 0.01905" quat="0.5 0.5 0.5 0.5" mesh="disc_b__configuration__1lb" material="disc_b__configuration__1lb_material"/>
        <!-- Part arm_front__configuration__1lb -->
        <geom type="mesh" class="visual" pos="-1.2265e-17 -5.15477e-18 0.01905" quat="0.5 0.5 0.5 0.5" mesh="arm_front__configuration__1lb" material="arm_front__configuration__1lb_material"/>
        <geom type="mesh" class="collision" pos="-1.2265e-17 -5.15477e-18 0.01905" quat="0.5 0.5 0.5 0.5" mesh="arm_front__configuration__1lb" material="arm_front__configuration__1lb_material"/>
        <!-- Part spacer3__configuration__1lb -->
        <geom type="mesh" class="visual" pos="-2.48011e-17 5.16962e-19 0.01905" quat="0.5 0.5 0.5 0.5" mesh="spacer3__configuration__1lb" material="spacer3__configuration__1lb_material"/>
        <geom type="mesh" class="collision" pos="-2.48011e-17 5.16962e-19 0.01905" quat="0.5 0.5 0.5 0.5" mesh="spacer3__configuration__1lb" material="spacer3__configuration__1lb_material"/>
        <!-- Part arm_rear__configuration__1lb -->
        <geom type="mesh" class="visual" pos="-1.27123e-17 1.1575e-17 0.01895" quat="0.5 0.5 0.5 0.5" mesh="arm_rear__configuration__1lb" material="arm_rear__configuration__1lb_material"/>
        <geom type="mesh" class="collision" pos="-1.27123e-17 1.1575e-17 0.01895" quat="0.5 0.5 0.5 0.5" mesh="arm_rear__configuration__1lb" material="arm_rear__configuration__1lb_material"/>
      </body>
    </body>
  </worldbody>
  <asset>
    <mesh file="spacer4__configuration__1lb.stl"/>
    <mesh file="motor_holder__configuration__1lb.stl"/>
    <mesh file="spacer3__configuration__1lb.stl"/>
    <mesh file="arm_rear__configuration__1lb.stl"/>
    <mesh file="disc_b__configuration__1lb.stl"/>
    <mesh file="axle_a__configuration__1lb.stl"/>
    <mesh file="arm_front__configuration__1lb.stl"/>
    <mesh file="sts3215.stl"/>
    <material name="sts3215_material" rgba="1 0 0 1"/>
    <material name="motor_holder__configuration__1lb_material" rgba="0.615686 0.811765 0.929412 1"/>
    <material name="spacer4__configuration__1lb_material" rgba="0.980392 0.713725 0.00392157 1"/>
    <material name="axle_a__configuration__1lb_material" rgba="0.231373 0.380392 0.705882 1"/>
    <material name="disc_b__configuration__1lb_material" rgba="0.980392 0.713725 0.00392157 1"/>
    <material name="arm_front__configuration__1lb_material" rgba="0.647059 0.647059 0.647059 1"/>
    <material name="spacer3__configuration__1lb_material" rgba="0.980392 0.713725 0.00392157 1"/>
    <material name="arm_rear__configuration__1lb_material" rgba="0.647059 0.647059 0.647059 1"/>
  </asset>
  <actuator>
      <motor class="arm_150_mass_b" name="sts3215_ctrl" joint="sts3215" gear="1" forcerange="-5.890154259732506 5.890154259732506"/>
  </actuator>
  <equality/>
</mujoco>
