<?xml version="1.0" ?>
<!-- Generated using onshape-to-robot -->
<!-- Onshape https://cad.onshape.com/documents/03d3216bcac5903908a6e0de/w/9c3caedc2611d4b7bfb40d56/e/290b00edac81cf5efebd2188 -->
<mujoco model="arm_100_mass_cd">
  <compiler angle="radian" meshdir="assets" autolimits="true"/>
  <default>
    <default class="arm_100_mass_cd">
       <joint 
        armature="0.026176125067127395" 
        frictionloss="0.09090098640882"
        damping="1.2965935100389328"
      />
      <default class="visual">
        <geom type="mesh" contype="0" conaffinity="0" group="2"/>
      </default>
      <default class="collision">
        <geom group="3"/>
      </default>
    </default>
  </default>
  <worldbody>
    <!-- Link motor_holder__configuration__1lb -->
    <body name="motor_holder__configuration__1lb" pos="0 0 0" quat="1 0 0 0" childclass="arm_100_mass_cd">
      <inertial pos="8.90348e-08 0.0151625 0.0438794" mass="0.0593939" fullinertia="4.21552e-05 1.0144e-05 4.23761e-05 -9.45235e-12 1.06843e-10 -5.33782e-06"/>
      <!-- Part sts3215 -->
      <geom type="mesh" class="visual" pos="6.93893e-18 -0.0096 0.025435" quat="2.4677e-16 -0.707107 -3.14018e-16 -0.707107" mesh="sts3215" material="sts3215_material"/>
      <geom type="mesh" class="collision" pos="6.93893e-18 -0.0096 0.025435" quat="2.4677e-16 -0.707107 -3.14018e-16 -0.707107" mesh="sts3215" material="sts3215_material"/>
      <!-- Part motor_holder__configuration__1lb -->
      <geom type="mesh" class="visual" pos="0 0 0" quat="1 0 0 0" mesh="motor_holder__configuration__1lb" material="motor_holder__configuration__1lb_material"/>
      <geom type="mesh" class="collision" pos="0 0 0" quat="1 0 0 0" mesh="motor_holder__configuration__1lb" material="motor_holder__configuration__1lb_material"/>
      <!-- Link axle_a__configuration__1lb -->
      <body name="axle_a__configuration__1lb" pos="1.38708e-17 -0.0187997 -6.5e-05" quat="0.5 -0.5 -0.5 -0.5">
        <!-- Joint from motor_holder__configuration__1lb to axle_a__configuration__1lb -->
        <joint name="sts3215" type="hinge" range="-1.7177371141078754 1.6507483422411806"/>
        <inertial pos="-0.147179 -0.00493151 0.0202427" mass="0.776" fullinertia="0.000942185 0.00113453 0.00192634 -6.45212e-06 4.02005e-06 1.347e-07"/>
        <!-- Part spacer_set1_rear__configuration__1lb -->
        <geom type="mesh" class="visual" pos="-0.105163 -0.0862913 0.036" quat="0.491557 0.491557 0.508303 0.508303" mesh="spacer_set1_rear__configuration__1lb" material="spacer_set1_rear__configuration__1lb_material"/>
        <geom type="mesh" class="collision" pos="-0.105163 -0.0862913 0.036" quat="0.491557 0.491557 0.508303 0.508303" mesh="spacer_set1_rear__configuration__1lb" material="spacer_set1_rear__configuration__1lb_material"/>
        <!-- Part disc_d__configuration__1lb -->
        <geom type="mesh" class="visual" pos="2.32106e-15 -3.36369e-16 0.012875" quat="0.491557 0.491557 0.508303 0.508303" mesh="disc_d__configuration__1lb" material="disc_d__configuration__1lb_material"/>
        <geom type="mesh" class="collision" pos="2.32106e-15 -3.36369e-16 0.012875" quat="0.491557 0.491557 0.508303 0.508303" mesh="disc_d__configuration__1lb" material="disc_d__configuration__1lb_material"/>
        <!-- Part axle_a__configuration__1lb -->
        <geom type="mesh" class="visual" pos="-1.63064e-16 -1.65371e-16 0.0188" quat="0.491557 0.491557 0.508303 0.508303" mesh="axle_a__configuration__1lb" material="axle_a__configuration__1lb_material"/>
        <geom type="mesh" class="collision" pos="-1.63064e-16 -1.65371e-16 0.0188" quat="0.491557 0.491557 0.508303 0.508303" mesh="axle_a__configuration__1lb" material="axle_a__configuration__1lb_material"/>
        <!-- Part disc_c__configuration__1lb -->
        <geom type="mesh" class="visual" pos="2.328e-15 -5.38567e-16 0.02425" quat="0.491557 0.491557 0.508303 0.508303" mesh="disc_c__configuration__1lb" material="disc_c__configuration__1lb_material"/>
        <geom type="mesh" class="collision" pos="2.328e-15 -5.38567e-16 0.02425" quat="0.491557 0.491557 0.508303 0.508303" mesh="disc_c__configuration__1lb" material="disc_c__configuration__1lb_material"/>
        <!-- Part arm_front__configuration__1lb -->
        <geom type="mesh" class="visual" pos="-1.66086e-16 -1.65374e-16 0.01905" quat="0.491557 0.491557 0.508303 0.508303" mesh="arm_front__configuration__1lb" material="arm_front__configuration__1lb_material"/>
        <geom type="mesh" class="collision" pos="-1.66086e-16 -1.65374e-16 0.01905" quat="0.491557 0.491557 0.508303 0.508303" mesh="arm_front__configuration__1lb" material="arm_front__configuration__1lb_material"/>
        <!-- Part arm_rear__configuration__1lb -->
        <geom type="mesh" class="visual" pos="-1.34861e-16 -2.40644e-16 0.01885" quat="0.491557 0.491557 0.508303 0.508303" mesh="arm_rear__configuration__1lb" material="arm_rear__configuration__1lb_material"/>
        <geom type="mesh" class="collision" pos="-1.34861e-16 -2.40644e-16 0.01885" quat="0.491557 0.491557 0.508303 0.508303" mesh="arm_rear__configuration__1lb" material="arm_rear__configuration__1lb_material"/>
        <!-- Part spacer_set1_front__configuration__1lb -->
        <geom type="mesh" class="visual" pos="-0.197873 -0.0864455 0.00725" quat="0.491557 0.491557 0.508303 0.508303" mesh="spacer_set1_front__configuration__1lb" material="spacer_set1_front__configuration__1lb_material"/>
        <geom type="mesh" class="collision" pos="-0.197873 -0.0864455 0.00725" quat="0.491557 0.491557 0.508303 0.508303" mesh="spacer_set1_front__configuration__1lb" material="spacer_set1_front__configuration__1lb_material"/>
      </body>
    </body>
  </worldbody>
  <asset>
    <mesh file="spacer_set1_rear__configuration__1lb.stl"/>
    <mesh file="motor_holder__configuration__1lb.stl"/>
    <mesh file="arm_front__configuration__1lb.stl"/>
    <mesh file="sts3215.stl"/>
    <mesh file="disc_c__configuration__1lb.stl"/>
    <mesh file="axle_a__configuration__1lb.stl"/>
    <mesh file="arm_rear__configuration__1lb.stl"/>
    <mesh file="spacer_set1_front__configuration__1lb.stl"/>
    <mesh file="disc_d__configuration__1lb.stl"/>
    <material name="sts3215_material" rgba="1 0 0 1"/>
    <material name="motor_holder__configuration__1lb_material" rgba="0.615686 0.811765 0.929412 1"/>
    <material name="spacer_set1_rear__configuration__1lb_material" rgba="0.917647 0.917647 0.917647 1"/>
    <material name="disc_d__configuration__1lb_material" rgba="1 0 0 1"/>
    <material name="axle_a__configuration__1lb_material" rgba="0.231373 0.380392 0.705882 1"/>
    <material name="disc_c__configuration__1lb_material" rgba="0.980392 0.713725 0.00392157 1"/>
    <material name="arm_front__configuration__1lb_material" rgba="0.647059 0.647059 0.647059 1"/>
    <material name="arm_rear__configuration__1lb_material" rgba="0.647059 0.647059 0.647059 1"/>
    <material name="spacer_set1_front__configuration__1lb_material" rgba="0.231373 0.380392 0.705882 1"/>
  </asset>
  <actuator>
      <motor class="arm_100_mass_cd" name="sts3215_ctrl" joint="sts3215" gear="1" forcerange="-5.890154259732506 5.890154259732506"/>
  </actuator>
  <equality/>
</mujoco>
